<?xml version="1.0" ?>
<robot name="xMate3" xmlns:xacro="http://www.ros.org/wiki/xacro">
  <material name="black">
    <color rgba="0.0 0.0 0.0 1.0"/>
  </material>
  <material name="blue">
    <color rgba="0.0 0.0 0.8 1.0"/>
  </material>
  <material name="green">
    <color rgba="0.0 0.8 0.0 1.0"/>
  </material>
  <material name="grey">
    <color rgba="0.2 0.2 0.2 1.0"/>
  </material>
  <material name="orange">
    <color rgba="1.0 0.423529411765 0.0392156862745 1.0"/>
  </material>
  <material name="brown">
    <color rgba="0.870588235294 0.811764705882 0.764705882353 1.0"/>
  </material>
  <material name="red">
    <color rgba="0.8 0.0 0.0 1.0"/>
  </material>
  <material name="white">
    <color rgba="1.0 1.0 1.0 1.0"/>
  </material>
  <material name="Beige">
    <color rgba="1.0 0.784 0.5765 1.0"/>
  </material>
  <!-- Used for fixing robot to Gazebo 'base_link' -->
  <link name="world"/>
  <joint name="fixed" type="fixed">
    <parent link="world"/>
    <child link="xMate3_base"/>
  </joint>
  <!--base-->
  <link name="xMate3_base">
    <visual>
      <geometry>
        <mesh filename="package://rokae_xmate3_ros2/meshes/visual/xMate3_base.stl" scale="0.001 0.001 0.001"/>
      </geometry>
      <origin rpy="0 0 0" xyz="0.0 0.0 0.0"/>
      <material name="white"/>
    </visual>
    <inertial>
    <mass value="3.44074938"/>
    <inertia ixx="0.0176" ixy="0" ixz="0" 
            iyy="0.0166" iyz="0" 
            izz="0.0172"/>
    <origin rpy="0 0 0" xyz="-0.000072769597 -0.01679187012 0.2986854502"/>
    </inertial>
    <collision>
      <geometry>
        <mesh filename="package://rokae_xmate3_ros2/meshes/collision/xMate3_base.stl" scale="0.001 0.001 0.001"/>
      </geometry>
      <origin rpy="0 0 0" xyz="0.0 0.0 0.0"/>
    </collision>
  </link>
  <joint name="xmate_joint_1" type="revolute">
    <parent link="xMate3_base"/>
    <child link="xMate3_link1"/>
    <limit effort="300" lower="-3.0527" upper="3.0527" velocity="10"/>
    <axis xyz="0 0 1"/>
    <origin rpy="0 0 0" xyz="0 0 0"/>
    <!-- ✅ 添加阻尼 -->
    <dynamics damping="1.0"/>
  </joint>
  <transmission name="tran1">
    <type>transmission_interface/SimpleTransmission</type>
    <joint name="xmate_joint_1">
      <hardwareInterface>EffortJointInterface</hardwareInterface>
    </joint>
    <actuator name="motor1">
      <hardwareInterface>EffortJointInterface</hardwareInterface>
      <mechanicalReduction>1</mechanicalReduction>
    </actuator>
  </transmission>
  <!--link 1-->
  <link name="xMate3_link1">
    <visual>
      <geometry>
        <mesh filename="package://rokae_xmate3_ros2/meshes/visual/xMate3_link1.stl" scale="0.001 0.001 0.001"/>
      </geometry>
      <origin rpy="0 0 0" xyz="0 0 0"/>
      <material name="white"/>
    </visual>
    <inertial>
    <mass value="3.44074938"/>
    <inertia ixx="0.0176" ixy="0" ixz="0" 
            iyy="0.0166" iyz="0" 
            izz="0.0342"/>
    <origin rpy="0 0 0" xyz="-0.000072769597 -0.01679187012 0.2986854502"/>
    </inertial>
    <collision>
      <geometry>
        <mesh filename="package://rokae_xmate3_ros2/meshes/collision/xMate3_link1.stl" scale="0.001 0.001 0.001"/>
      </geometry>
      <origin rpy="0 0 0" xyz="0 0 0"/>
    </collision>
  </link>
  <joint name="xmate_joint_2" type="revolute">
    <parent link="xMate3_link1"/>
    <child link="xMate3_link2"/>
    <limit effort="300" lower="-2.0933" upper="2.0933" velocity="10"/>
    <axis xyz="0 1 0"/>
    <origin rpy="0 0 0" xyz="0 0 0.3415"/>
    <!-- ✅ 添加阻尼 -->
    <dynamics damping="1.0"/>
  </joint>
  <transmission name="tran2">
    <type>transmission_interface/SimpleTransmission</type>
    <joint name="xmate_joint_2">
      <hardwareInterface>EffortJointInterface</hardwareInterface>
    </joint>
    <actuator name="motor2">
      <hardwareInterface>EffortJointInterface</hardwareInterface>
      <mechanicalReduction>1</mechanicalReduction>
    </actuator>
  </transmission>
  <!--link 2-->
  <link name="xMate3_link2">
    <visual>
      <geometry>
        <mesh filename="package://rokae_xmate3_ros2/meshes/visual/xMate3_link2.stl" scale="0.001 0.001 0.001"/>
      </geometry>
      <origin rpy="0 0 0" xyz="0 0 0.0"/>
      <material name="white"/>
    </visual>
    <inertial>
    <mass value="5.024380503"/>
    <inertia ixx="0.145" ixy="0" ixz="0" iyy="0.148" iyz="-0.024" izz="0.015"/>
    <origin rpy="0 0 0" xyz="0 0.003491209523 0.2410487354"/>
    </inertial>
    <collision>
      <geometry>
        <mesh filename="package://rokae_xmate3_ros2/meshes/collision/xMate3_link2.stl" scale="0.001 0.001 0.001"/>
      </geometry>
      <origin rpy="0 0 0" xyz="0 0 0.0"/>
    </collision>
  </link>
  <joint name="xmate_joint_3" type="revolute">
    <parent link="xMate3_link2"/>
    <child link="xMate3_link3"/>
    <limit effort="300" lower="-2.0933" upper="2.0933" velocity="10"/>
    <axis xyz="0 1 0"/>
    <origin rpy="0 0 0" xyz="0 0 0.394"/>
    <!-- ✅ 添加阻尼 -->
    <dynamics damping="1.0"/>
  </joint>
  <transmission name="tran3">
    <type>transmission_interface/SimpleTransmission</type>
    <joint name="xmate_joint_3">
      <hardwareInterface>EffortJointInterface</hardwareInterface>
    </joint>
    <actuator name="motor3">
      <hardwareInterface>EffortJointInterface</hardwareInterface>
      <mechanicalReduction>1</mechanicalReduction>
    </actuator>
  </transmission>
  <!--link 3-->
  <link name="xMate3_link3">
    <visual>
      <geometry>
        <mesh filename="package://rokae_xmate3_ros2/meshes/visual/xMate3_link3.stl" scale="0.001 0.001 0.001"/>
      </geometry>
      <origin rpy="0 0 0" xyz="0 0 0"/>
      <material name="white"/>
    </visual>
    <inertial>
    <mass value="2.439584706"/>
    <inertia ixx="0.0262" ixy="0" ixz="0" 
            iyy="0.0243" iyz="0" 
            izz="0.0505"/>
    <origin rpy="0 0 0" xyz="0 0.023 0.097"/>
    </inertial>
    <collision>
      <geometry>
        <mesh filename="package://rokae_xmate3_ros2/meshes/collision/xMate3_link3.stl" scale="0.001 0.001 0.001"/>
      </geometry>
      <origin rpy="0 0 0" xyz="0 0 0"/>
    </collision>
  </link>
  <joint name="xmate_joint_4" type="revolute">
    <parent link="xMate3_link3"/>
    <child link="xMate3_link4"/>
    <limit effort="300" lower="-3.0527" upper="3.0527" velocity="10"/>
    <axis xyz="0 0 1"/>
    <origin rpy="0 0 0" xyz="0 0 0.366"/>
    <!-- ✅ 添加阻尼 -->
    <dynamics damping="1.0"/>
  </joint>
  <transmission name="tran4">
    <type>transmission_interface/SimpleTransmission</type>
    <joint name="xmate_joint_4">
      <hardwareInterface>EffortJointInterface</hardwareInterface>
    </joint>
    <actuator name="motor4">
      <hardwareInterface>EffortJointInterface</hardwareInterface>
      <mechanicalReduction>1</mechanicalReduction>
    </actuator>
  </transmission>
  <!--link 4-->
  <link name="xMate3_link4">
    <visual>
      <geometry>
        <mesh filename="package://rokae_xmate3_ros2/meshes/visual/xMate3_link4.stl" scale="0.001 0.001 0.001"/>
      </geometry>
      <origin rpy="0 0 0" xyz="0.0 0.0 0.0"/>
      <material name="white"/>
    </visual>
    <inertial>
    <mass value="2.439584706"/>
    <inertia ixx="0.022" ixy="0" ixz="0" 
            iyy="0.022" iyz="0" 
            izz="0.004"/>
    <origin rpy="0 0 0" xyz="0 -0.020 -0.046"/>
    </inertial>
    <collision>
      <geometry>
        <mesh filename="package://rokae_xmate3_ros2/meshes/collision/xMate3_link4.stl" scale="0.001 0.001 0.001"/>
      </geometry>
      <origin rpy="0 0 0" xyz="0.0 0.0 0.0"/>
    </collision>
  </link>
  <joint name="xmate_joint_5" type="revolute">
    <parent link="xMate3_link4"/>
    <child link="xMate3_link5"/>
    <limit effort="300" lower="-2.0933" upper="2.0933" velocity="10"/>
    <axis xyz="0 1 0"/>
    <origin rpy="0 0 0" xyz="0 0 0"/>
    <!-- ✅ 添加阻尼 -->
    <dynamics damping="1.0"/>
  </joint>
  <transmission name="tran5">
    <type>transmission_interface/SimpleTransmission</type>
    <joint name="xmate_joint_5">
      <hardwareInterface>EffortJointInterface</hardwareInterface>
    </joint>
    <actuator name="motor5">
      <hardwareInterface>EffortJointInterface</hardwareInterface>
      <mechanicalReduction>1</mechanicalReduction>
    </actuator>
  </transmission>
  <!--link 5-->
  <link name="xMate3_link5">
    <visual>
      <geometry>
        <mesh filename="package://rokae_xmate3_ros2/meshes/visual/xMate3_link5.stl" scale="0.001 0.001 0.001"/>
      </geometry>
      <origin rpy="0 0 0" xyz="0 0 0"/>
      <material name="white"/>
    </visual>
    <inertial>
    <mass value="2.422757896"/>
    <inertia ixx="0.016" ixy="0" ixz="0" 
            iyy="0.015" iyz="0" 
            izz="0.031"/>
    <origin rpy="0 0 0" xyz="0 0.012 0.096"/>
    </inertial>
    <collision>
      <geometry>
        <mesh filename="package://rokae_xmate3_ros2/meshes/collision/xMate3_link5.stl" scale="0.001 0.001 0.001"/>
      </geometry>
      <origin rpy="0 0 0" xyz="0 0 0"/>
    </collision>
  </link>
  <joint name="xmate_joint_6" type="revolute">
    <parent link="xMate3_link5"/>
    <child link="xMate3_link6"/>
    <limit effort="300" lower="-6.1082" upper="6.1082" velocity="10"/>
    <axis xyz="0 0 1"/>
    <origin rpy="0.0 0.0 0" xyz="0 0 0.2503"/>
    <!-- ✅ 添加阻尼 -->
    <dynamics damping="1.0"/>
  </joint>
  <transmission name="tran6">
    <type>transmission_interface/SimpleTransmission</type>
    <joint name="xmate_joint_6">
      <hardwareInterface>EffortJointInterface</hardwareInterface>
    </joint>
    <actuator name="motor6">
      <hardwareInterface>EffortJointInterface</hardwareInterface>
      <mechanicalReduction>1</mechanicalReduction>
    </actuator>
  </transmission>
  <!--link 6-->
  <link name="xMate3_link6">
    <visual>
      <geometry>
        <mesh filename="package://rokae_xmate3_ros2/meshes/visual/xMate3_link6.stl" scale="0.001 0.001 0.001"/>
      </geometry>
      <origin rpy="0 0 0" xyz="0.0 0.0 0.0"/>
      <material name="white"/>
    </visual>
    <inertial>
    <mass value="1.229800857"/>
    <inertia ixx="0.002" ixy="0" ixz="0" 
            iyy="0.002" iyz="0" 
            izz="0.002"/>
    <origin rpy="0 0 0" xyz="0 0.017 -0.043"/>
    </inertial>
    <collision>
      <geometry>
        <mesh filename="package://rokae_xmate3_ros2/meshes/collision/xMate3_link6.stl" scale="0.001 0.001 0.001"/>
      </geometry>
      <origin rpy="0 0 0" xyz="0.0 0.0 0.0"/>
    </collision>
  </link>
  <gazebo>
    <plugin name="gazebo_joint_state_publisher" filename="libgazebo_ros_joint_state_publisher.so">
      <frame_name>world</frame_name>
      <joint_name>xmate_joint_1</joint_name>
      <joint_name>xmate_joint_2</joint_name>
      <joint_name>xmate_joint_3</joint_name>
      <joint_name>xmate_joint_4</joint_name>
      <joint_name>xmate_joint_5</joint_name>
      <joint_name>xmate_joint_6</joint_name>
      <update_rate>50</update_rate>
    </plugin>
  </gazebo>
</robot>